<mujoco model="WA1_D11">
  <compiler angle="radian" meshdir="./meshes/"/>

  <asset>
    <mesh name="BASE" content_type="model/stl" file="BASE.STL"/>
    <mesh name="BODY" content_type="model/stl" file="BODY.STL"/>
    <mesh name="TORSO" content_type="model/stl" file="TORSO.STL"/>
    <mesh name="CHEST" content_type="model/stl" file="CHEST.STL"/>
    <mesh name="SCAPULA_L" content_type="model/stl" file="SCAPULA_L.STL"/>
    <mesh name="SHOULDER_L" content_type="model/stl" file="SHOULDER_L.STL"/>
    <mesh name="UPPERARM_L" content_type="model/stl" file="UPPERARM_L.STL"/>
    <mesh name="FOREARM_L" content_type="model/stl" file="FOREARM_L.STL"/>
    <mesh name="WRIST_REVOLUTE_L" content_type="model/stl" file="WRIST_REVOLUTE_L.STL"/>
    <mesh name="WRIST_UPDOWN_L" content_type="model/stl" file="WRIST_UPDOWN_L.STL"/>
    <mesh name="WRIST_FLANGE_L" content_type="model/stl" file="WRIST_FLANGE_L.STL"/>
    <mesh name="TCP_L" content_type="model/stl" file="TCP_L.STL"/>
    <mesh name="HAND_L" content_type="model/stl" file="HAND_L.STL"/>
    <mesh name="SCAPULA_R" content_type="model/stl" file="SCAPULA_R.STL"/>
    <mesh name="SHOULDER_R" content_type="model/stl" file="SHOULDER_R.STL"/>
    <mesh name="UPPERARM_R" content_type="model/stl" file="UPPERARM_R.STL"/>
    <mesh name="FOREARM_R" content_type="model/stl" file="FOREARM_R.STL"/>
    <mesh name="WRIST_REVOLUTE_R" content_type="model/stl" file="WRIST_REVOLUTE_R.STL"/>
    <mesh name="WRIST_UPDOWN_R" content_type="model/stl" file="WRIST_UPDOWN_R.STL"/>
    <mesh name="WRIST_FLANGE_R" content_type="model/stl" file="WRIST_FLANGE_R.STL"/>
    <mesh name="TCP_R" content_type="model/stl" file="TCP_R.STL"/>
    <mesh name="HAND_R" content_type="model/stl" file="HAND_R.STL"/>
    <mesh name="NECK" content_type="model/stl" file="NECK.STL"/>
    <mesh name="HEAD" content_type="model/stl" file="HEAD.STL"/>
    <mesh name="Lift_Front_Direction" content_type="model/stl" file="Lift_Front_Direction.STL"/>
    <mesh name="Lift_Front_Roll" content_type="model/stl" file="Lift_Front_Roll.STL"/>
    <mesh name="Right_Front_Direction" content_type="model/stl" file="Right_Front_Direction.STL"/>
    <mesh name="Right_Front_Roll" content_type="model/stl" file="Right_Front_Roll.STL"/>
    <mesh name="Lift_Behind_Direction" content_type="model/stl" file="Lift_Behind_Direction.STL"/>
    <mesh name="Lift_Behind_Roll" content_type="model/stl" file="Lift_Behind_Roll.STL"/>
    <mesh name="Right_Behind_Direction" content_type="model/stl" file="Right_Behind_Direction.STL"/>
    <mesh name="Right_Behind_Roll" content_type="model/stl" file="Right_Behind_Roll.STL"/>
    <mesh name="Lift_Roll" content_type="model/stl" file="Lift_Roll.STL"/>
    <mesh name="Right_Roll" content_type="model/stl" file="Right_Roll.STL"/>
    <mesh name="index_Link1_L" content_type="model/stl" file="index_Link1_L.STL"/>
    <mesh name="index_Link2_L" content_type="model/stl" file="index_Link2_L.STL"/>
    <mesh name="index_Link3_L" content_type="model/stl" file="index_Link3_L.STL"/>
    <mesh name="thumb_Link1_L" content_type="model/stl" file="thumb_Link1_L.STL"/>
    <mesh name="thumb_Link2_L" content_type="model/stl" file="thumb_Link2_L.STL"/>
    <mesh name="thumb_Link3_L" content_type="model/stl" file="thumb_Link3_L.STL"/>
    <mesh name="middle_Link1_L" content_type="model/stl" file="middle_Link1_L.STL"/>
    <mesh name="middle_Link2_L" content_type="model/stl" file="middle_Link2_L.STL"/>
    <mesh name="middle_Link3_L" content_type="model/stl" file="middle_Link3_L.STL"/>
    <mesh name="ring_Link1_L" content_type="model/stl" file="ring_Link1_L.STL"/>
    <mesh name="ring_Link2_L" content_type="model/stl" file="ring_Link2_L.STL"/>
    <mesh name="ring_Link3_L" content_type="model/stl" file="ring_Link3_L.STL"/>
    <mesh name="little_Link1_L" content_type="model/stl" file="little_Link1_L.STL"/>
    <mesh name="little_Link2_L" content_type="model/stl" file="little_Link2_L.STL"/>
    <mesh name="little_Link3_L" content_type="model/stl" file="little_Link3_L.STL"/>
    <mesh name="index_Link1_R" content_type="model/stl" file="index_Link1_R.STL"/>
    <mesh name="index_Link2_R" content_type="model/stl" file="index_Link2_R.STL"/>
    <mesh name="index_Link3_R" content_type="model/stl" file="index_Link3_R.STL"/>
    <mesh name="thumb_Link1_R" content_type="model/stl" file="thumb_Link1_R.STL"/>
    <mesh name="thumb_Link2_R" content_type="model/stl" file="thumb_Link2_R.STL"/>
    <mesh name="thumb_Link3_R" content_type="model/stl" file="thumb_Link3_R.STL"/>
    <mesh name="middle_Link1_R" content_type="model/stl" file="middle_Link1_R.STL"/>
    <mesh name="middle_Link2_R" content_type="model/stl" file="middle_Link2_R.STL"/>
    <mesh name="middle_Link3_R" content_type="model/stl" file="middle_Link3_R.STL"/>
    <mesh name="ring_Link1_R" content_type="model/stl" file="ring_Link1_R.STL"/>
    <mesh name="ring_Link2_R" content_type="model/stl" file="ring_Link2_R.STL"/>
    <mesh name="ring_Link3_R" content_type="model/stl" file="ring_Link3_R.STL"/>
    <mesh name="little_Link1_R" content_type="model/stl" file="little_Link1_R.STL"/>
    <mesh name="little_Link2_R" content_type="model/stl" file="little_Link2_R.STL"/>
    <mesh name="little_Link3_R" content_type="model/stl" file="little_Link3_R.STL"/>
  </asset>

  <worldbody>
    <geom type="mesh" contype="0" conaffinity="0" group="1" density="0" rgba="0.737255 0.901961 0.952941 1" mesh="BASE"/>
    <geom type="mesh" rgba="0.737255 0.901961 0.952941 1" mesh="BASE"/>
    <body name="BODY" pos="0.31 0 0.492">
      <inertial pos="0.00347376 4.29529e-05 0.0269981" quat="0.99995 0.00128669 -0.00983926 0.00158201" mass="2.26151" diaginertia="0.0112114 0.00891637 0.00587214"/>
      <joint name="Lifting_Z" pos="0 0 0" axis="0 0 1" type="slide" range="0 0.25" actuatorfrcrange="-6780 6780"/>
      <geom type="mesh" contype="0" conaffinity="0" group="1" density="0" rgba="0.890196 0.890196 0.913725 1" mesh="BODY"/>
      <geom type="mesh" rgba="0.890196 0.890196 0.913725 1" mesh="BODY"/>
      <body name="TORSO" pos="0 0 0.1561">
        <inertial pos="2.41417e-05 -0.0132281 0.0596889" quat="0.529111 0.459571 -0.47401 0.533057" mass="1.86507" diaginertia="0.00437662 0.00430109 0.00399179"/>
        <joint name="Waist_Z" pos="0 0 0" axis="0 0 1" range="-2.0944 3.2289" actuatorfrcrange="-290 290"/>
        <geom type="mesh" contype="0" conaffinity="0" group="1" density="0" rgba="0.898039 0.917647 0.929412 1" mesh="TORSO"/>
        <geom type="mesh" rgba="0.898039 0.917647 0.929412 1" mesh="TORSO"/>
        <body name="CHEST" pos="0 0 0.0744">
          <inertial pos="0.0012812 0.00209651 0.351464" quat="0.995815 -0.0906375 -0.00716393 -0.00932637" mass="3.56126" diaginertia="0.0301585 0.0219493 0.0158067"/>
          <joint name="Waist_Y" pos="0 0 0" axis="0 1 0" range="-0.5236 0.7854" actuatorfrcrange="-290 290"/>
          <geom type="mesh" contype="0" conaffinity="0" group="1" density="0" rgba="0.866667 0.866667 0.890196 1" mesh="CHEST"/>
          <geom type="mesh" rgba="0.866667 0.866667 0.890196 1" mesh="CHEST"/>
          <body name="SCAPULA_L" pos="0.0074317 0.16387 0.39" quat="0.965926 0 0 -0.25882">
            <inertial pos="-0.00040196 0.0700578 -9.26072e-05" quat="0.116849 0.694592 0.157753 0.6921" mass="1.11871" diaginertia="0.00135689 0.00119239 0.00111172"/>
            <joint name="Shoulder_Y_L" pos="0 0 0" axis="0 1 0" range="-3.31 1.22" actuatorfrcrange="-57 57"/>
            <geom type="mesh" contype="0" conaffinity="0" group="1" density="0" rgba="0.341176 1 0.768627 1" mesh="SCAPULA_L"/>
            <geom type="mesh" rgba="0.341176 1 0.768627 1" mesh="SCAPULA_L"/>
            <body name="SHOULDER_L" pos="0 0.075202 0" quat="0.984807 -0.17365 0 0">
              <inertial pos="0.021673 0.001368 -0.036388" quat="-0.0630331 0.909694 -0.154724 0.38019" mass="0.24116" diaginertia="0.000494678 0.000437833 0.000240489"/>
              <joint name="Shoulder_X_L" pos="0 0 0" axis="1 0 0" range="-0.008 3.14" actuatorfrcrange="-57 57"/>
              <geom type="mesh" contype="0" conaffinity="0" group="1" density="0" rgba="0.898039 0.917647 0.929412 1" mesh="SHOULDER_L"/>
              <geom type="mesh" rgba="0.898039 0.917647 0.929412 1" mesh="SHOULDER_L"/>
              <body name="UPPERARM_L" pos="0 0 -0.0845">
                <inertial pos="-0.000571741 0.000196201 -0.0734512" quat="0.999962 -0.0018085 -0.00272148 0.00812032" mass="1.70224" diaginertia="0.0073432 0.00728906 0.00112974"/>
                <joint name="Shoulder_Z_L" pos="0 0 0" axis="0 0 1" range="-2.94 2.94" actuatorfrcrange="-57 57"/>
                <geom type="mesh" contype="0" conaffinity="0" group="1" density="0" rgba="0.0431373 1 0.909804 1" mesh="UPPERARM_L"/>
                <geom type="mesh" rgba="0.0431373 1 0.909804 1" mesh="UPPERARM_L"/>
                <body name="FOREARM_L" pos="0 0 -0.1555">
                  <inertial pos="-0.00293207 -0.00206216 -0.0303657" quat="0.747508 0.664098 -0.00664177 0.012739" mass="0.209975" diaginertia="0.000350037 0.000310157 0.000224806"/>
                  <joint name="Elbow_L" pos="0 0 0" axis="0 1 0" range="-2.09 0.08" actuatorfrcrange="-31 31"/>
                  <geom type="mesh" contype="0" conaffinity="0" group="1" density="0" rgba="0.898039 0.917647 0.929412 1" mesh="FOREARM_L"/>
                  <geom type="mesh" rgba="0.898039 0.917647 0.929412 1" mesh="FOREARM_L"/>
                  <body name="WRIST_REVOLUTE_L" pos="0 0 -0.0685">
                    <inertial pos="5.7727e-05 0.0017166 -0.068778" quat="0.713373 -0.0146232 0.0156277 0.700458" mass="1.455" diaginertia="0.00428408 0.00427001 0.000959912"/>
                    <joint name="Wrist_Z_L" pos="0 0 0" axis="0 0 1" range="-2.96 2.96" actuatorfrcrange="-25 25"/>
                    <geom type="mesh" contype="0" conaffinity="0" group="1" density="0" rgba="0.898039 0.917647 0.929412 1" mesh="WRIST_REVOLUTE_L"/>
                    <geom type="mesh" rgba="0.898039 0.917647 0.929412 1" mesh="WRIST_REVOLUTE_L"/>
                    <body name="WRIST_UPDOWN_L" pos="0 0 -0.1385">
                      <inertial pos="0.0035454 0.00067359 -0.053675" quat="0.996589 0.0629415 0.0439295 -0.0303013" mass="0.48691" diaginertia="0.000423434 0.000379041 0.000246525"/>
                      <joint name="Wrist_Y_L" pos="0 0 0" axis="0 1 0" range="-1.57 1.57" actuatorfrcrange="-16 16"/>
                      <geom type="mesh" contype="0" conaffinity="0" group="1" density="0" rgba="0.898039 0.917647 0.929412 1" mesh="WRIST_UPDOWN_L"/>
                      <geom type="mesh" rgba="0.898039 0.917647 0.929412 1" mesh="WRIST_UPDOWN_L"/>
                      <body name="WRIST_FLANGE_L" pos="0 0 -0.063">
                        <inertial pos="0.00922839 0.00128365 -0.114452" quat="0.74991 -0.0234905 -0.017378 0.660894" mass="0.667475" diaginertia="0.00217273 0.00174604 0.000563355"/>
                        <joint name="Wrist_X_L" pos="0 0 0" axis="1 0 0" range="-1.57 1.57" actuatorfrcrange="-16 16"/>
                        <geom type="mesh" contype="0" conaffinity="0" group="1" density="0" rgba="0.898039 0.917647 0.929412 1" mesh="WRIST_FLANGE_L"/>
                        <geom type="mesh" rgba="0.898039 0.917647 0.929412 1" mesh="WRIST_FLANGE_L"/>
                        <geom pos="0 0 -0.060997" quat="1 0 0 0" type="mesh" contype="0" conaffinity="0" group="1" density="0" rgba="0.247059 0.392157 1 1" mesh="TCP_L"/>
                        <geom pos="0 0 -0.060997" quat="1 0 0 0" type="mesh" rgba="0.247059 0.392157 1 1" mesh="TCP_L"/>
                        <geom pos="0 0 -0.060997" quat="1.34924e-11 3.67321e-06 -1 -3.67321e-06" type="mesh" contype="0" conaffinity="0" group="1" density="0" rgba="0.792157 0.819608 0.933333 1" mesh="HAND_L"/>
                        <geom pos="0 0 -0.060997" quat="1.34924e-11 3.67321e-06 -1 -3.67321e-06" type="mesh" rgba="0.792157 0.819608 0.933333 1" mesh="HAND_L"/>
                        <body name="index_Link1_L" pos="0.033581 0.00500105 -0.171007" quat="2.68639e-06 -0.731348 -2.50514e-06 0.682005">
                          <inertial pos="0.018514 -0.00061104 -4.4346e-07" quat="0.49669 0.49669 0.503274 0.503302" mass="0.011981" diaginertia="1.57659e-06 1.2249e-06 4.90651e-07"/>
                          <joint name="index_MCP_L" pos="0 0 0" axis="0 0 1" range="0 1.5" actuatorfrcrange="-1 1"/>
                          <geom type="mesh" contype="0" conaffinity="0" group="1" density="0" rgba="0.79216 0.81961 0.93333 1" mesh="index_Link1_L"/>
                          <geom type="mesh" rgba="0.79216 0.81961 0.93333 1" mesh="index_Link1_L"/>
                          <body name="index_Link2_L" pos="0.0415 0 0">
                            <inertial pos="0.00828247 -0.00194105 -1.12966e-07" quat="0.478961 0.479145 0.520188 0.520021" mass="0.00600739" diaginertia="5.39974e-07 3.07932e-07 2.67883e-07"/>
                            <joint name="index_PIP_L" pos="0 0 0" axis="0 0 1" range="0 1.5" actuatorfrcrange="-1 1"/>
                            <geom type="mesh" contype="0" conaffinity="0" group="1" density="0" rgba="0.792157 0.819608 0.933333 1" mesh="index_Link2_L"/>
                            <geom type="mesh" rgba="0.792157 0.819608 0.933333 1" mesh="index_Link2_L"/>
                            <body name="index_Link3_L" pos="0.0245 0 0">
                              <inertial pos="0.011297 -0.0007036 8.3368e-07" quat="0.501658 0.501626 0.49843 0.498276" mass="0.0040088" diaginertia="2.17305e-07 1.5733e-07 9.03395e-08"/>
                              <joint name="index_DIP_L" pos="0 0 0" axis="0 0 1" range="0 1.5" actuatorfrcrange="-1 1"/>
                              <geom type="mesh" contype="0" conaffinity="0" group="1" density="0" rgba="0.79216 0.81961 0.93333 1" mesh="index_Link3_L"/>
                              <geom type="mesh" rgba="0.79216 0.81961 0.93333 1" mesh="index_Link3_L"/>
                            </body>
                          </body>
                        </body>
                        <body name="thumb_Link1_L" pos="0.03 0.00500045 -0.091997" quat="3.67321e-06 -1 0 2.69849e-11">
                          <inertial pos="0.0234553 0.00651952 0.00708996" quat="0.946566 -0.210588 0.240655 0.0418427" mass="0.0698989" diaginertia="2.02756e-05 1.84829e-05 6.53317e-06"/>
                          <joint name="thumb_CMC_L" pos="0 0 0" axis="0 0 1" range="-0.5 1.5" actuatorfrcrange="-1 1"/>
                          <geom type="mesh" contype="0" conaffinity="0" group="1" density="0" rgba="0.792157 0.819608 0.933333 1" mesh="thumb_Link1_L"/>
                          <geom type="mesh" rgba="0.792157 0.819608 0.933333 1" mesh="thumb_Link1_L"/>
                          <body name="thumb_Link2_L" pos="0.037554 0.019018 0.029117" quat="0.664462 0.500001 -0.241843 0.500001">
                            <inertial pos="0.0195783 0.00226682 -1.29808e-06" quat="0.511001 0.510637 0.488814 0.489069" mass="0.0140065" diaginertia="1.86395e-06 1.2635e-06 9.38662e-07"/>
                            <joint name="thumb_MP_L" pos="0 0 0" axis="0 0 1" range="-1 1" actuatorfrcrange="-1 1"/>
                            <geom type="mesh" contype="0" conaffinity="0" group="1" density="0" rgba="0.792157 0.819608 0.933333 1" mesh="thumb_Link2_L"/>
                            <geom type="mesh" rgba="0.792157 0.819608 0.933333 1" mesh="thumb_Link2_L"/>
                            <body name="thumb_Link3_L" pos="0.04 0 0">
                              <inertial pos="0.0154271 0.000308171 4.61447e-05" quat="0.515304 0.51695 0.48059 0.486063" mass="0.00698528" diaginertia="5.93746e-07 4.44911e-07 2.44773e-07"/>
                              <joint name="thumb_IP_L" pos="0 0 0" axis="0 0 1" range="0 1" actuatorfrcrange="-1 1"/>
                              <geom type="mesh" contype="0" conaffinity="0" group="1" density="0" rgba="0.792157 0.819608 0.933333 1" mesh="thumb_Link3_L"/>
                              <geom type="mesh" rgba="0.792157 0.819608 0.933333 1" mesh="thumb_Link3_L"/>
                            </body>
                          </body>
                        </body>
                        <body name="middle_Link1_L" pos="0.012 0.00500095 -0.177997" quat="2.59734e-06 0.707108 7.79204e-06 -0.707105">
                          <inertial pos="0.0185143 -0.000611045 -4.44086e-07" quat="0.49669 0.49669 0.503274 0.503303" mass="0.0119813" diaginertia="1.57656e-06 1.22493e-06 4.90653e-07"/>
                          <joint name="middle_MCP_L" pos="0 0 0" axis="0 0 1" range="0 1.5" actuatorfrcrange="-1 1"/>
                          <geom type="mesh" contype="0" conaffinity="0" group="1" density="0" rgba="0.792157 0.819608 0.933333 1" mesh="middle_Link1_L"/>
                          <geom type="mesh" rgba="0.792157 0.819608 0.933333 1" mesh="middle_Link1_L"/>
                          <body name="middle_Link2_L" pos="0.0415 0 0">
                            <inertial pos="0.00828243 -0.00194104 -1.40231e-07" quat="0.478964 0.479142 0.520183 0.520025" mass="0.0060074" diaginertia="5.39975e-07 3.07933e-07 2.67883e-07"/>
                            <joint name="middle_PIP_L" pos="0 0 0" axis="0 0 1" range="0 1.5" actuatorfrcrange="-1 1"/>
                            <geom type="mesh" contype="0" conaffinity="0" group="1" density="0" rgba="0.792157 0.819608 0.933333 1" mesh="middle_Link2_L"/>
                            <geom type="mesh" rgba="0.792157 0.819608 0.933333 1" mesh="middle_Link2_L"/>
                            <body name="middle_Link3_L" pos="0.0245 0 0">
                              <inertial pos="0.0112969 -0.00070372 5.44644e-07" quat="0.501637 0.50164 0.498397 0.498316" mass="0.00400866" diaginertia="2.17295e-07 1.57321e-07 9.03293e-08"/>
                              <joint name="middle_DIP_L" pos="0 0 0" axis="0 0 1" range="0 1.5" actuatorfrcrange="-1 1"/>
                              <geom type="mesh" contype="0" conaffinity="0" group="1" density="0" rgba="0.792157 0.819608 0.933333 1" mesh="middle_Link3_L"/>
                              <geom type="mesh" rgba="0.792157 0.819608 0.933333 1" mesh="middle_Link3_L"/>
                            </body>
                          </body>
                        </body>
                        <body name="ring_Link1_L" pos="-0.00958154 0.00500074 -0.171007" quat="2.68639e-06 0.682005 7.87792e-06 -0.731348">
                          <inertial pos="0.0185143 -0.000611056 -4.46346e-07" quat="0.49669 0.496689 0.503274 0.503303" mass="0.0119813" diaginertia="1.57657e-06 1.22493e-06 4.90653e-07"/>
                          <joint name="ring_MCP_L" pos="0 0 0" axis="0 0 1" range="0 1.5" actuatorfrcrange="-1 1"/>
                          <geom type="mesh" contype="0" conaffinity="0" group="1" density="0" rgba="0.792157 0.819608 0.933333 1" mesh="ring_Link1_L"/>
                          <geom type="mesh" rgba="0.792157 0.819608 0.933333 1" mesh="ring_Link1_L"/>
                          <body name="ring_Link2_L" pos="0.0415 0 0">
                            <inertial pos="0.00828244 -0.00194104 -1.35037e-07" quat="0.478965 0.479142 0.520183 0.520025" mass="0.00600742" diaginertia="5.39976e-07 3.07934e-07 2.67883e-07"/>
                            <joint name="ring_PIP_L" pos="0 0 0" axis="0 0 1" range="0 1.5" actuatorfrcrange="-1 1"/>
                            <geom type="mesh" contype="0" conaffinity="0" group="1" density="0" rgba="0.792157 0.819608 0.933333 1" mesh="ring_Link2_L"/>
                            <geom type="mesh" rgba="0.792157 0.819608 0.933333 1" mesh="ring_Link2_L"/>
                            <body name="ring_Link3_L" pos="0.0245 0 0">
                              <inertial pos="0.0112969 -0.000703764 4.49516e-07" quat="0.50163 0.501643 0.498383 0.498333" mass="0.00400863" diaginertia="2.17292e-07 1.57319e-07 9.03262e-08"/>
                              <joint name="ring_DIP_L" pos="0 0 0" axis="0 0 1" range="0 1.5" actuatorfrcrange="-1 1"/>
                              <geom type="mesh" contype="0" conaffinity="0" group="1" density="0" rgba="0.792157 0.819608 0.933333 1" mesh="ring_Link3_L"/>
                              <geom type="mesh" rgba="0.792157 0.819608 0.933333 1" mesh="ring_Link3_L"/>
                            </body>
                          </body>
                        </body>
                        <body name="little_Link1_L" pos="-0.031165 0.00500053 -0.164057" quat="2.77217e-06 0.65607 7.95421e-06 -0.7547">
                          <inertial pos="0.018514 -0.00061105 -4.4692e-07" quat="0.49669 0.496689 0.503274 0.503303" mass="0.011981" diaginertia="1.57659e-06 1.2249e-06 4.90651e-07"/>
                          <joint name="little_MCP_L" pos="0 0 0" axis="0 0 1" range="0 1.5" actuatorfrcrange="-1 1"/>
                          <geom type="mesh" contype="0" conaffinity="0" group="1" density="0" rgba="0.79216 0.81961 0.93333 1" mesh="little_Link1_L"/>
                          <geom type="mesh" rgba="0.79216 0.81961 0.93333 1" mesh="little_Link1_L"/>
                          <body name="little_Link2_L" pos="0.0415 0 0">
                            <inertial pos="0.0082824 -0.001941 -1.3751e-07" quat="0.478964 0.479143 0.520184 0.520024" mass="0.0060074" diaginertia="5.39971e-07 3.0793e-07 2.67879e-07"/>
                            <joint name="little_PIP_L" pos="0 0 0" axis="0 0 1" range="0 1.5" actuatorfrcrange="-1 1"/>
                            <geom type="mesh" contype="0" conaffinity="0" group="1" density="0" rgba="0.79216 0.81961 0.93333 1" mesh="little_Link2_L"/>
                            <geom type="mesh" rgba="0.79216 0.81961 0.93333 1" mesh="little_Link2_L"/>
                            <body name="little_Link3_L" pos="0.0245 0 0">
                              <inertial pos="0.011297 -0.00070377 4.4851e-07" quat="0.501631 0.501642 0.498382 0.498334" mass="0.0040086" diaginertia="2.17295e-07 1.5732e-07 9.03265e-08"/>
                              <joint name="little_DIP_L" pos="0 0 0" axis="0 0 1" range="0 1.5" actuatorfrcrange="-1 1"/>
                              <geom type="mesh" contype="0" conaffinity="0" group="1" density="0" rgba="0.79216 0.81961 0.93333 1" mesh="little_Link3_L"/>
                              <geom type="mesh" rgba="0.79216 0.81961 0.93333 1" mesh="little_Link3_L"/>
                            </body>
                          </body>
                        </body>
                      </body>
                    </body>
                  </body>
                </body>
              </body>
            </body>
          </body>
          <body name="SCAPULA_R" pos="0.0074317 -0.16387 0.39" quat="0.965926 0 0 0.25882">
            <inertial pos="-0.000401938 -0.0700579 -9.25479e-05" quat="-0.116849 0.694592 -0.157753 0.6921" mass="1.11871" diaginertia="0.00135689 0.00119239 0.00111172"/>
            <joint name="Shoulder_Y_R" pos="0 0 0" axis="0 1 0" range="-3.31 1.22" actuatorfrcrange="-57 57"/>
            <geom type="mesh" contype="0" conaffinity="0" group="1" density="0" rgba="0.898039 0.917647 0.929412 1" mesh="SCAPULA_R"/>
            <geom type="mesh" rgba="0.898039 0.917647 0.929412 1" mesh="SCAPULA_R"/>
            <body name="SHOULDER_R" pos="0 -0.075202 0" quat="0.984807 0.17365 0 0">
              <inertial pos="0.021655 -0.0013531 -0.03639" quat="0.0633241 0.909858 0.156079 0.379193" mass="0.240961" diaginertia="0.000494228 0.000437778 0.000239994"/>
              <joint name="Shoulder_X_R" pos="0 0 0" axis="1 0 0" range="-3.14 0.008" actuatorfrcrange="-57 57"/>
              <geom type="mesh" contype="0" conaffinity="0" group="1" density="0" rgba="0.898039 0.917647 0.929412 1" mesh="SHOULDER_R"/>
              <geom type="mesh" rgba="0.898039 0.917647 0.929412 1" mesh="SHOULDER_R"/>
              <body name="UPPERARM_R" pos="0 0 -0.0845">
                <inertial pos="-0.00057166 -0.000199247 -0.073521" quat="0.999994 0.00186187 -0.00281606 0.00120124" mass="1.70222" diaginertia="0.0073492 0.00729509 0.00112972"/>
                <joint name="Shoulder_Z_R" pos="0 0 0" axis="0 0 1" range="-2.94 2.94" actuatorfrcrange="-57 57"/>
                <geom type="mesh" contype="0" conaffinity="0" group="1" density="0" rgba="0.898039 0.917647 0.929412 1" mesh="UPPERARM_R"/>
                <geom type="mesh" rgba="0.898039 0.917647 0.929412 1" mesh="UPPERARM_R"/>
                <body name="FOREARM_R" pos="0 0 -0.1555">
                  <inertial pos="-0.00302173 0.00211862 -0.0303563" quat="0.664096 0.747502 -0.0130254 0.00685861" mass="0.210684" diaginertia="0.000350038 0.000311156 0.000225806"/>
                  <joint name="Elbow_R" pos="0 0 0" axis="0 1 0" range="-2.09 0.08" actuatorfrcrange="-31 31"/>
                  <geom type="mesh" contype="0" conaffinity="0" group="1" density="0" rgba="0.898039 0.917647 0.929412 1" mesh="FOREARM_R"/>
                  <geom type="mesh" rgba="0.898039 0.917647 0.929412 1" mesh="FOREARM_R"/>
                  <body name="WRIST_REVOLUTE_R" pos="0 0 -0.0685">
                    <inertial pos="5.7765e-05 -0.0017166 -0.068778" quat="0.700458 0.0156277 -0.0146232 0.713373" mass="1.455" diaginertia="0.00428408 0.00427001 0.000959912"/>
                    <joint name="Wrist_Z_R" pos="0 0 0" axis="0 0 1" range="-2.96 2.96" actuatorfrcrange="-25 25"/>
                    <geom type="mesh" contype="0" conaffinity="0" group="1" density="0" rgba="0.898039 0.917647 0.929412 1" mesh="WRIST_REVOLUTE_R"/>
                    <geom type="mesh" rgba="0.898039 0.917647 0.929412 1" mesh="WRIST_REVOLUTE_R"/>
                    <body name="WRIST_UPDOWN_R" pos="0 0 -0.1385">
                      <inertial pos="0.0035804 -0.00054646 -0.053983" quat="0.997399 -0.0516639 0.0430355 0.0259795" mass="0.48452" diaginertia="0.000412293 0.000368263 0.000245444"/>
                      <joint name="Wrist_Y_R" pos="0 0 0" axis="0 1 0" range="-1.57 1.57" actuatorfrcrange="-16 16"/>
                      <geom type="mesh" contype="0" conaffinity="0" group="1" density="0" rgba="0.898039 0.917647 0.929412 1" mesh="WRIST_UPDOWN_R"/>
                      <geom type="mesh" rgba="0.898039 0.917647 0.929412 1" mesh="WRIST_UPDOWN_R"/>
                      <body name="WRIST_FLANGE_R" pos="0 0 -0.063">
                        <inertial pos="0.00924765 -0.00177613 -0.114846" quat="0.671835 -0.0212553 -0.0297496 0.739798" mass="0.66755" diaginertia="0.00213516 0.00169685 0.000566122"/>
                        <joint name="Wrist_X_R" pos="0 0 0" axis="1 0 0" range="-1.57 1.57" actuatorfrcrange="-16 16"/>
                        <geom type="mesh" contype="0" conaffinity="0" group="1" density="0" rgba="0.898039 0.917647 0.929412 1" mesh="WRIST_FLANGE_R"/>
                        <geom type="mesh" rgba="0.898039 0.917647 0.929412 1" mesh="WRIST_FLANGE_R"/>
                        <geom pos="0 0 -0.060997" quat="1 0 0 0" type="mesh" contype="0" conaffinity="0" group="1" density="0" rgba="0.247059 0.392157 1 1" mesh="TCP_R"/>
                        <geom pos="0 0 -0.060997" quat="1 0 0 0" type="mesh" rgba="0.247059 0.392157 1 1" mesh="TCP_R"/>
                        <geom pos="0 0 -0.060997" quat="1.34924e-11 3.67321e-06 1 3.67321e-06" type="mesh" contype="0" conaffinity="0" group="1" density="0" rgba="0.792157 0.819608 0.933333 1" mesh="HAND_R"/>
                        <geom pos="0 0 -0.060997" quat="1.34924e-11 3.67321e-06 1 3.67321e-06" type="mesh" rgba="0.792157 0.819608 0.933333 1" mesh="HAND_R"/>
                        <body name="index_Link1_R" pos="0.033581 -0.00499944 -0.171007" quat="-7.69668e-06 0.731348 -2.86764e-06 -0.682005">
                          <inertial pos="0.018514 0.00061106 4.4636e-07" quat="0.503274 0.503303 0.49669 0.496689" mass="0.011981" diaginertia="1.57659e-06 1.2249e-06 4.90651e-07"/>
                          <joint name="index_MCP_R" pos="0 0 0" axis="0 0 -1" range="0 1.5" actuatorfrcrange="-1 1"/>
                          <geom type="mesh" contype="0" conaffinity="0" group="1" density="0" rgba="0.79216 0.81961 0.93333 1" mesh="index_Link1_R"/>
                          <geom type="mesh" rgba="0.79216 0.81961 0.93333 1" mesh="index_Link1_R"/>
                          <body name="index_Link2_R" pos="0.0415 0 0">
                            <inertial pos="0.0082824 0.001941 1.3975e-07" quat="0.520184 0.520023 0.478963 0.479143" mass="0.0060074" diaginertia="5.39971e-07 3.0793e-07 2.67879e-07"/>
                            <joint name="index_PIP_R" pos="0 0 0" axis="0 0 -1" range="0 1.5" actuatorfrcrange="-1 1"/>
                            <geom type="mesh" contype="0" conaffinity="0" group="1" density="0" rgba="0.79216 0.81961 0.93333 1" mesh="index_Link2_R"/>
                            <geom type="mesh" rgba="0.79216 0.81961 0.93333 1" mesh="index_Link2_R"/>
                            <body name="index_Link3_R" pos="0.0245 0 0">
                              <inertial pos="0.011297 0.00070376 -4.4927e-07" quat="0.498383 0.498333 0.50163 0.501643" mass="0.0040086" diaginertia="2.17295e-07 1.5732e-07 9.03265e-08"/>
                              <joint name="index_DIP_R" pos="0 0 0" axis="0 0 -1" range="0 1.5" actuatorfrcrange="-1 1"/>
                              <geom type="mesh" contype="0" conaffinity="0" group="1" density="0" rgba="0.79216 0.81961 0.93333 1" mesh="index_Link3_R"/>
                              <geom type="mesh" rgba="0.79216 0.81961 0.93333 1" mesh="index_Link3_R"/>
                            </body>
                          </body>
                        </body>
                        <body name="thumb_Link1_R" pos="0.03 -0.00499999 -0.091997" quat="-3.67321e-06 1 -7.34641e-06 0">
                          <inertial pos="0.023451 -0.0065156 0.0070806" quat="0.946591 0.210335 0.240747 -0.0420076" mass="0.069915" diaginertia="2.02824e-05 1.8488e-05 6.53467e-06"/>
                          <joint name="thumb_CMC_R" pos="0 0 0" axis="0 0 -1" range="-0.5 1.5" actuatorfrcrange="-1 1"/>
                          <geom type="mesh" contype="0" conaffinity="0" group="1" density="0" rgba="0.79216 0.81961 0.93333 1" mesh="thumb_Link1_R"/>
                          <geom type="mesh" rgba="0.79216 0.81961 0.93333 1" mesh="thumb_Link1_R"/>
                          <body name="thumb_Link2_R" pos="0.037554 -0.019018 0.029117" quat="0.664462 -0.500001 -0.241843 -0.500001">
                            <inertial pos="0.019578 -0.0022668 1.3145e-06" quat="0.488816 0.489068 0.510999 0.510639" mass="0.014007" diaginertia="1.86397e-06 1.2635e-06 9.38659e-07"/>
                            <joint name="thumb_MP_R" pos="0 0 0" axis="0 0 -1" range="-1 1" actuatorfrcrange="-1 1"/>
                            <geom type="mesh" contype="0" conaffinity="0" group="1" density="0" rgba="0.79216 0.81961 0.93333 1" mesh="thumb_Link2_R"/>
                            <geom type="mesh" rgba="0.79216 0.81961 0.93333 1" mesh="thumb_Link2_R"/>
                            <body name="thumb_Link3_R" pos="0.04 0 0">
                              <inertial pos="0.015427 -0.00030817 -4.6143e-05" quat="0.48059 0.486064 0.515305 0.516949" mass="0.0069853" diaginertia="5.93748e-07 4.44915e-07 2.44777e-07"/>
                              <joint name="thumb_IP_R" pos="0 0 0" axis="0 0 -1" range="0 1" actuatorfrcrange="-1 1"/>
                              <geom type="mesh" contype="0" conaffinity="0" group="1" density="0" rgba="0.79216 0.81961 0.93333 1" mesh="thumb_Link3_R"/>
                              <geom type="mesh" rgba="0.79216 0.81961 0.93333 1" mesh="thumb_Link3_R"/>
                            </body>
                          </body>
                        </body>
                        <body name="middle_Link1_R" pos="0.012 -0.00499923 -0.177997" quat="-7.79205e-06 0.707108 -2.59735e-06 -0.707105">
                          <inertial pos="0.018514 0.00061105 4.4528e-07" quat="0.503274 0.503303 0.49669 0.49669" mass="0.011981" diaginertia="1.57659e-06 1.2249e-06 4.90651e-07"/>
                          <joint name="middle_MCP_R" pos="0 0 0" axis="0 0 -1" range="0 1.5" actuatorfrcrange="-1 1"/>
                          <geom type="mesh" contype="0" conaffinity="0" group="1" density="0" rgba="0.79216 0.81961 0.93333 1" mesh="middle_Link1_R"/>
                          <geom type="mesh" rgba="0.79216 0.81961 0.93333 1" mesh="middle_Link1_R"/>
                          <body name="middle_Link2_R" pos="0.0415 0 0">
                            <inertial pos="0.0082825 0.001941 1.1803e-07" quat="0.520188 0.52002 0.478961 0.479146" mass="0.0060074" diaginertia="5.39971e-07 3.0793e-07 2.67879e-07"/>
                            <joint name="middle_PIP_R" pos="0 0 0" axis="0 0 -1" range="0 1.5" actuatorfrcrange="-1 1"/>
                            <geom type="mesh" contype="0" conaffinity="0" group="1" density="0" rgba="0.79216 0.81961 0.93333 1" mesh="middle_Link2_R"/>
                            <geom type="mesh" rgba="0.79216 0.81961 0.93333 1" mesh="middle_Link2_R"/>
                            <body name="middle_Link3_R" pos="0.0245 0 0">
                              <inertial pos="0.011297 0.00070372 -5.4465e-07" quat="0.498397 0.498316 0.501637 0.50164" mass="0.0040087" diaginertia="2.17295e-07 1.5732e-07 9.03295e-08"/>
                              <joint name="middle_DIP_R" pos="0 0 0" axis="0 0 -1" range="0 1.5" actuatorfrcrange="-1 1"/>
                              <geom type="mesh" contype="0" conaffinity="0" group="1" density="0" rgba="0.79216 0.81961 0.93333 1" mesh="middle_Link3_R"/>
                              <geom type="mesh" rgba="0.79216 0.81961 0.93333 1" mesh="middle_Link3_R"/>
                            </body>
                          </body>
                        </body>
                        <body name="ring_Link1_R" pos="-0.00958154 -0.00499912 -0.171007" quat="-7.69668e-06 0.682005 -2.50514e-06 -0.731348">
                          <inertial pos="0.018514 0.00061104 4.4446e-07" quat="0.503274 0.503303 0.49669 0.49669" mass="0.011981" diaginertia="1.57659e-06 1.2249e-06 4.90651e-07"/>
                          <joint name="ring_MCP_R" pos="0 0 0" axis="0 0 -1" range="0 1.5" actuatorfrcrange="-1 1"/>
                          <geom type="mesh" contype="0" conaffinity="0" group="1" density="0" rgba="0.79216 0.81961 0.93333 1" mesh="ring_Link1_R"/>
                          <geom type="mesh" rgba="0.79216 0.81961 0.93333 1" mesh="ring_Link1_R"/>
                          <body name="ring_Link2_R" pos="0.0415 0 0">
                            <inertial pos="0.0082825 0.0019411 1.0664e-07" quat="0.520187 0.52002 0.478961 0.479145" mass="0.0060074" diaginertia="5.39971e-07 3.0793e-07 2.67879e-07"/>
                            <joint name="ring_PIP_R" pos="0 0 0" axis="0 0 -1" range="0 1.5" actuatorfrcrange="-1 1"/>
                            <geom type="mesh" contype="0" conaffinity="0" group="1" density="0" rgba="0.79216 0.81961 0.93333 1" mesh="ring_Link2_R"/>
                            <geom type="mesh" rgba="0.79216 0.81961 0.93333 1" mesh="ring_Link2_R"/>
                            <body name="ring_Link3_R" pos="0.0245 0 0">
                              <inertial pos="0.011297 0.0007036 -8.3367e-07" quat="0.49843 0.498276 0.501658 0.501626" mass="0.0040088" diaginertia="2.17305e-07 1.5733e-07 9.03395e-08"/>
                              <joint name="ring_DIP_R" pos="0 0 0" axis="0 0 -1" range="0 1.5" actuatorfrcrange="-1 1"/>
                              <geom type="mesh" contype="0" conaffinity="0" group="1" density="0" rgba="0.79216 0.81961 0.93333 1" mesh="ring_Link3_R"/>
                              <geom type="mesh" rgba="0.79216 0.81961 0.93333 1" mesh="ring_Link3_R"/>
                            </body>
                          </body>
                        </body>
                        <body name="little_Link1_R" pos="-0.031165 -0.00499901 -0.164057" quat="-7.59193e-06 0.65607 -2.40988e-06 -0.7547">
                          <inertial pos="0.018514 0.00061104 4.4526e-07" quat="0.503274 0.503303 0.49669 0.49669" mass="0.011981" diaginertia="1.57659e-06 1.2249e-06 4.90651e-07"/>
                          <joint name="little_MCP_R" pos="0 0 0" axis="0 0 -1" range="0 1.5" actuatorfrcrange="-1 1"/>
                          <geom type="mesh" contype="0" conaffinity="0" group="1" density="0" rgba="0.79216 0.81961 0.93333 1" mesh="little_Link1_R"/>
                          <geom type="mesh" rgba="0.79216 0.81961 0.93333 1" mesh="little_Link1_R"/>
                          <body name="little_Link2_R" pos="0.0415 0 0">
                            <inertial pos="0.0082824 0.001941 1.3548e-07" quat="0.520182 0.520026 0.478965 0.479141" mass="0.0060074" diaginertia="5.39971e-07 3.0793e-07 2.67879e-07"/>
                            <joint name="little_PIP_R" pos="0 0 0" axis="0 0 -1" range="0 1.5" actuatorfrcrange="-1 1"/>
                            <geom type="mesh" contype="0" conaffinity="0" group="1" density="0" rgba="0.79216 0.81961 0.93333 1" mesh="little_Link2_R"/>
                            <geom type="mesh" rgba="0.79216 0.81961 0.93333 1" mesh="little_Link2_R"/>
                            <body name="little_Link3_R" pos="0.0245 0 0">
                              <inertial pos="0.011297 0.00070363 -7.8629e-07" quat="0.498427 0.49828 0.501651 0.501631" mass="0.0040088" diaginertia="2.17305e-07 1.5732e-07 9.03375e-08"/>
                              <joint name="little_DIP_R" pos="0 0 0" axis="0 0 -1" range="0 1.5" actuatorfrcrange="-1 1"/>
                              <geom type="mesh" contype="0" conaffinity="0" group="1" density="0" rgba="0.79216 0.81961 0.93333 1" mesh="little_Link3_R"/>
                              <geom type="mesh" rgba="0.79216 0.81961 0.93333 1" mesh="little_Link3_R"/>
                            </body>
                          </body>
                        </body>
                      </body>
                    </body>
                  </body>
                </body>
              </body>
            </body>
          </body>
          <body name="NECK" pos="0 0 0.531">
            <inertial pos="-0.000120663 0.000126274 0.0384337" quat="0.918481 0.395465 0 0" mass="0.256801" diaginertia="0.000108 9.55139e-05 7.74861e-05"/>
            <joint name="Neck_Z" pos="0 0 0" axis="0 0 1" range="-0.785 0.785" actuatorfrcrange="-7 7"/>
            <geom type="mesh" contype="0" conaffinity="0" group="1" density="0" rgba="0.898039 0.917647 0.929412 1" mesh="NECK"/>
            <geom type="mesh" rgba="0.898039 0.917647 0.929412 1" mesh="NECK"/>
            <body name="HEAD" pos="0 0 0.042">
              <inertial pos="0.0158688 -0.000733077 0.0794555" quat="0.636199 0.272076 0.203362 0.692726" mass="0.727085" diaginertia="0.00261995 0.0023937 0.00181935"/>
              <joint name="Neck_Y" pos="0 0 0" axis="0 1 0" range="-0.17 0.34" actuatorfrcrange="-7 7"/>
              <geom type="mesh" contype="0" conaffinity="0" group="1" density="0" rgba="0.898039 0.917647 0.929412 1" mesh="HEAD"/>
              <geom type="mesh" rgba="0.898039 0.917647 0.929412 1" mesh="HEAD"/>
            </body>
          </body>
        </body>
      </body>
    </body>
    <body name="Lift_Front_Direction" pos="0.3325 0.155 -0.144">
      <inertial pos="6.36259e-05 0.00419322 -0.023331" quat="0.0180784 0.706338 0.0329576 0.706876" mass="0.170568" diaginertia="0.000165718 0.000121063 8.90923e-05"/>
      <joint name="L_F_D" pos="0 0 0" axis="0 0 1"/>
      <geom type="mesh" contype="0" conaffinity="0" group="1" density="0" rgba="0.792157 0.819608 0.92549 1" mesh="Lift_Front_Direction"/>
      <geom type="mesh" rgba="0.792157 0.819608 0.92549 1" mesh="Lift_Front_Direction"/>
      <body name="Lift_Front_Roll" pos="-0.00045701 0.021695 -0.068" quat="0.999945 0 0 0.0105308">
        <inertial pos="0 0 0" mass="0.273883" diaginertia="0.000192269 0.000180306 0.000180306"/>
        <joint name="L_F_Roll" pos="0 0 0" axis="1 0 0"/>
        <geom type="mesh" contype="0" conaffinity="0" group="1" density="0" rgba="0.792157 0.819608 0.933333 1" mesh="Lift_Front_Roll"/>
        <geom type="mesh" rgba="0.792157 0.819608 0.933333 1" mesh="Lift_Front_Roll"/>
      </body>
    </body>
    <body name="Right_Front_Direction" pos="0.3325 -0.155 -0.144">
      <inertial pos="0.00186425 0.00375651 -0.0233308" quat="0.173788 0.696169 -0.123889 0.685418" mass="0.170567" diaginertia="0.000165719 0.000121062 8.9094e-05"/>
      <joint name="R_F_D" pos="0 0 0" axis="0 0 1"/>
      <geom type="mesh" contype="0" conaffinity="0" group="1" density="0" rgba="0.792157 0.819608 0.92549 1" mesh="Right_Front_Direction"/>
      <geom type="mesh" rgba="0.792157 0.819608 0.92549 1" mesh="Right_Front_Direction"/>
      <body name="Right_Front_Roll" pos="0.0089363 0.019775 -0.068" quat="0.977566 0 0 -0.210631">
        <inertial pos="0 0 0" mass="0.273883" diaginertia="0.000192269 0.000180306 0.000180306"/>
        <joint name="R_F_Roll" pos="0 0 0" axis="1 0 0"/>
        <geom type="mesh" contype="0" conaffinity="0" group="1" density="0" rgba="0.792157 0.819608 0.933333 1" mesh="Right_Front_Roll"/>
        <geom type="mesh" rgba="0.792157 0.819608 0.933333 1" mesh="Right_Front_Roll"/>
      </body>
    </body>
    <body name="Lift_Behind_Direction" pos="-0.3325 0.155 -0.144">
      <inertial pos="0.00389583 -0.00155221 -0.0233308" quat="0.592306 0.427953 -0.5629 0.38623" mass="0.170567" diaginertia="0.000165719 0.000121062 8.9094e-05"/>
      <joint name="L_B_D" pos="0 0 0" axis="0 0 1"/>
      <geom type="mesh" contype="0" conaffinity="0" group="1" density="0" rgba="0.792157 0.819608 0.92549 1" mesh="Lift_Behind_Direction"/>
      <geom type="mesh" rgba="0.792157 0.819608 0.92549 1" mesh="Lift_Behind_Direction"/>
      <body name="Lift_Behind_Roll" pos="0.020436 -0.0072966 -0.068" quat="0.985336 0 0 -0.170626">
        <inertial pos="0 0 0" quat="0.707107 0 0 0.707107" mass="0.273883" diaginertia="0.000192269 0.000180306 0.000180306"/>
        <joint name="L_B_Roll" pos="0 0 0" axis="0 1 0"/>
        <geom type="mesh" contype="0" conaffinity="0" group="1" density="0" rgba="0.792157 0.819608 0.933333 1" mesh="Lift_Behind_Roll"/>
        <geom type="mesh" rgba="0.792157 0.819608 0.933333 1" mesh="Lift_Behind_Roll"/>
      </body>
    </body>
    <body name="Right_Behind_Direction" pos="-0.3325 -0.155 -0.144">
      <inertial pos="0.00334835 -0.00252494 -0.0233308" quat="0.638438 0.349234 -0.614846 0.303968" mass="0.170567" diaginertia="0.000165719 0.000121062 8.9094e-05"/>
      <joint name="R_B_D" pos="0 0 0" axis="0 0 1"/>
      <geom type="mesh" contype="0" conaffinity="0" group="1" density="0" rgba="0.792157 0.819608 0.92549 1" mesh="Right_Behind_Direction"/>
      <geom type="mesh" rgba="0.792157 0.819608 0.92549 1" mesh="Right_Behind_Direction"/>
      <body name="Right_Behind_Roll" pos="0.017788 -0.012429 -0.068" quat="0.953863 0 0 -0.300241">
        <inertial pos="0 0 0" quat="0.707107 0 0 0.707107" mass="0.273883" diaginertia="0.000192269 0.000180306 0.000180306"/>
        <joint name="R_B_Roll" pos="0 0 0" axis="0 1 0"/>
        <geom type="mesh" contype="0" conaffinity="0" group="1" density="0" rgba="0.792157 0.819608 0.933333 1" mesh="Right_Behind_Roll"/>
        <geom type="mesh" rgba="0.792157 0.819608 0.933333 1" mesh="Right_Behind_Roll"/>
      </body>
    </body>
    <body name="Lift_Roll" pos="0 0.235 -0.16">
      <inertial pos="0 0.00104537 0" quat="0.707107 0 0 0.707107" mass="0.847652" diaginertia="0.0045428 0.00243833 0.00243833"/>
      <joint name="Lift_Wheel" pos="0 0 0" axis="0 1 0"/>
      <geom type="mesh" contype="0" conaffinity="0" group="1" density="0" rgba="0.792157 0.819608 0.933333 1" mesh="Lift_Roll"/>
      <geom type="mesh" rgba="0.792157 0.819608 0.933333 1" mesh="Lift_Roll"/>
    </body>
    <body name="Right_Roll" pos="0 -0.235 -0.16">
      <inertial pos="0 -0.00104537 0" quat="0.707107 0 0 0.707107" mass="0.847652" diaginertia="0.0045428 0.00243833 0.00243833"/>
      <joint name="Right_Wheel" pos="0 0 0" axis="0 1 0"/>
      <geom type="mesh" contype="0" conaffinity="0" group="1" density="0" rgba="0.792157 0.819608 0.933333 1" mesh="Right_Roll"/>
      <geom type="mesh" rgba="0.792157 0.819608 0.933333 1" mesh="Right_Roll"/>
    </body>
  </worldbody>

  <actuator>
    <motor name="motor_Lifting_Z" joint="Lifting_Z" ctrlrange="-6780.0 6780.0" gear="1"/>
    <motor name="motor_Waist_Z" joint="Waist_Z" ctrlrange="-290.0 290.0" gear="1"/>
    <motor name="motor_Waist_Y" joint="Waist_Y" ctrlrange="-290.0 290.0" gear="1"/>
    <motor name="motor_Shoulder_Y_L" joint="Shoulder_Y_L" ctrlrange="-57.0 57.0" gear="1"/>
    <motor name="motor_Shoulder_X_L" joint="Shoulder_X_L" ctrlrange="-57.0 57.0" gear="1"/>
    <motor name="motor_Shoulder_Z_L" joint="Shoulder_Z_L" ctrlrange="-57.0 57.0" gear="1"/>
    <motor name="motor_Elbow_L" joint="Elbow_L" ctrlrange="-31.0 31.0" gear="1"/>
    <motor name="motor_Wrist_Z_L" joint="Wrist_Z_L" ctrlrange="-25.0 25.0" gear="1"/>
    <motor name="motor_Wrist_Y_L" joint="Wrist_Y_L" ctrlrange="-16.0 16.0" gear="1"/>
    <motor name="motor_Wrist_X_L" joint="Wrist_X_L" ctrlrange="-16.0 16.0" gear="1"/>
    <motor name="motor_index_MCP_L" joint="index_MCP_L" ctrlrange="-1.0 1.0" gear="1"/>
    <motor name="motor_index_PIP_L" joint="index_PIP_L" ctrlrange="-1.0 1.0" gear="1"/>
    <motor name="motor_index_DIP_L" joint="index_DIP_L" ctrlrange="-1.0 1.0" gear="1"/>
    <motor name="motor_thumb_CMC_L" joint="thumb_CMC_L" ctrlrange="-1.0 1.0" gear="1"/>
    <motor name="motor_thumb_MP_L" joint="thumb_MP_L" ctrlrange="-1.0 1.0" gear="1"/>
    <motor name="motor_thumb_IP_L" joint="thumb_IP_L" ctrlrange="-1.0 1.0" gear="1"/>
    <motor name="motor_middle_MCP_L" joint="middle_MCP_L" ctrlrange="-1.0 1.0" gear="1"/>
    <motor name="motor_middle_PIP_L" joint="middle_PIP_L" ctrlrange="-1.0 1.0" gear="1"/>
    <motor name="motor_middle_DIP_L" joint="middle_DIP_L" ctrlrange="-1.0 1.0" gear="1"/>
    <motor name="motor_ring_MCP_L" joint="ring_MCP_L" ctrlrange="-1.0 1.0" gear="1"/>
    <motor name="motor_ring_PIP_L" joint="ring_PIP_L" ctrlrange="-1.0 1.0" gear="1"/>
    <motor name="motor_ring_DIP_L" joint="ring_DIP_L" ctrlrange="-1.0 1.0" gear="1"/>
    <motor name="motor_little_MCP_L" joint="little_MCP_L" ctrlrange="-1.0 1.0" gear="1"/>
    <motor name="motor_little_PIP_L" joint="little_PIP_L" ctrlrange="-1.0 1.0" gear="1"/>
    <motor name="motor_little_DIP_L" joint="little_DIP_L" ctrlrange="-1.0 1.0" gear="1"/>
    <motor name="motor_Shoulder_Y_R" joint="Shoulder_Y_R" ctrlrange="-57.0 57.0" gear="1"/>
    <motor name="motor_Shoulder_X_R" joint="Shoulder_X_R" ctrlrange="-57.0 57.0" gear="1"/>
    <motor name="motor_Shoulder_Z_R" joint="Shoulder_Z_R" ctrlrange="-57.0 57.0" gear="1"/>
    <motor name="motor_Elbow_R" joint="Elbow_R" ctrlrange="-31.0 31.0" gear="1"/>
    <motor name="motor_Wrist_Z_R" joint="Wrist_Z_R" ctrlrange="-25.0 25.0" gear="1"/>
    <motor name="motor_Wrist_Y_R" joint="Wrist_Y_R" ctrlrange="-16.0 16.0" gear="1"/>
    <motor name="motor_Wrist_X_R" joint="Wrist_X_R" ctrlrange="-16.0 16.0" gear="1"/>
    <motor name="motor_index_MCP_R" joint="index_MCP_R" ctrlrange="-1.0 1.0" gear="1"/>
    <motor name="motor_index_PIP_R" joint="index_PIP_R" ctrlrange="-1.0 1.0" gear="1"/>
    <motor name="motor_index_DIP_R" joint="index_DIP_R" ctrlrange="-1.0 1.0" gear="1"/>
    <motor name="motor_thumb_CMC_R" joint="thumb_CMC_R" ctrlrange="-1.0 1.0" gear="1"/>
    <motor name="motor_thumb_MP_R" joint="thumb_MP_R" ctrlrange="-1.0 1.0" gear="1"/>
    <motor name="motor_thumb_IP_R" joint="thumb_IP_R" ctrlrange="-1.0 1.0" gear="1"/>
    <motor name="motor_middle_MCP_R" joint="middle_MCP_R" ctrlrange="-1.0 1.0" gear="1"/>
    <motor name="motor_middle_PIP_R" joint="middle_PIP_R" ctrlrange="-1.0 1.0" gear="1"/>
    <motor name="motor_middle_DIP_R" joint="middle_DIP_R" ctrlrange="-1.0 1.0" gear="1"/>
    <motor name="motor_ring_MCP_R" joint="ring_MCP_R" ctrlrange="-1.0 1.0" gear="1"/>
    <motor name="motor_ring_PIP_R" joint="ring_PIP_R" ctrlrange="-1.0 1.0" gear="1"/>
    <motor name="motor_ring_DIP_R" joint="ring_DIP_R" ctrlrange="-1.0 1.0" gear="1"/>
    <motor name="motor_little_MCP_R" joint="little_MCP_R" ctrlrange="-1.0 1.0" gear="1"/>
    <motor name="motor_little_PIP_R" joint="little_PIP_R" ctrlrange="-1.0 1.0" gear="1"/>
    <motor name="motor_little_DIP_R" joint="little_DIP_R" ctrlrange="-1.0 1.0" gear="1"/>
    <motor name="motor_Neck_Z" joint="Neck_Z" ctrlrange="-7.0 7.0" gear="1"/>
    <motor name="motor_Neck_Y" joint="Neck_Y" ctrlrange="-7.0 7.0" gear="1"/>
    <motor name="motor_L_F_D" joint="L_F_D" ctrlrange="-0.0 0.0" gear="1"/>
    <motor name="motor_L_F_Roll" joint="L_F_Roll" ctrlrange="-0.0 0.0" gear="1"/>
    <motor name="motor_R_F_D" joint="R_F_D" ctrlrange="-0.0 0.0" gear="1"/>
    <motor name="motor_R_F_Roll" joint="R_F_Roll" ctrlrange="-0.0 0.0" gear="1"/>
    <motor name="motor_L_B_D" joint="L_B_D" ctrlrange="-0.0 0.0" gear="1"/>
    <motor name="motor_L_B_Roll" joint="L_B_Roll" ctrlrange="-0.0 0.0" gear="1"/>
    <motor name="motor_R_B_D" joint="R_B_D" ctrlrange="-0.0 0.0" gear="1"/>
    <motor name="motor_R_B_Roll" joint="R_B_Roll" ctrlrange="-0.0 0.0" gear="1"/>
    <motor name="motor_Lift_Wheel" joint="Lift_Wheel" ctrlrange="-0.0 0.0" gear="1"/>
    <motor name="motor_Right_Wheel" joint="Right_Wheel" ctrlrange="-0.0 0.0" gear="1"/>
  </actuator>

  <keyframe>
    <key name="home" qpos="0 0 0 
    0 0.3 0 0 0 0 0 
    0 0 0 0 0 0 0 0 0 0 0 0 0 0 0
    0 -0.3 0 0 0 0 0
    0 0 0 0 0 0 0 0 0 0 0 0 0 0 0
    0 0 
    0 0 0 0 0 0 0 0 0 0
    "/>
  </keyframe>

</mujoco>
